Workbook

Sheet Information
B2: Compiled by Lenoire77
B4: All data obtained from TheSportsDB
B5: English Premier League - TheSportsDB.com

Sheet All Time Table
C1: TOTAL
A2: Team | B2: Seasons | C2: Wins | D2: Draws | E2: Losses | F2: Games Played | G2: Goals For | H2: Goals Against | I2: Goal Difference | J2: Points | K2: Position
A3: Manchester United | B3: =COUNTIF('All Years'!$B$2:$B$607,A3) -> 30 | C3: =SUMIF('All Years'!$B$2:$B$607,$A3,'All Years'!C$2:C$607) -> 703 | D3: =SUMIF('All Years'!$B$2:$B$607,$A3,'All Years'!D$2:D$607) -> 257 | E3: =SUMIF('All Years'!$B$2:$B$607,$A3,'All Years'!E$2:E$607) -> 192 | F3: =SUMIF('All Years'!$B$2:$B$607,$A3,'All Years'!F$2:F$607) -> 1152 | G3: =SUMIF('All Years'!$B$2:$B$607,$A3,'All Years'!G$2:G$607) -> 2185 | H3: =SUMIF('All Years'!$B$2:$B$607,$A3,'All Years'!H$2:H$607) -> 1066 | I3: =SUMIF('All Years'!$B$2:$B$607,$A3,'All Years'!I$2:I$607) -> 1119 | J3: =SUMIF('All Years'!$B$2:$B$607,$A3,'All Years'!J$2:J$607) -> 2366 | K3: 1
A4: Arsenal | B4: =COUNTIF('All Years'!$B$2:$B$607,A4) -> 30 | C4: =SUMIF('All Years'!$B$2:$B$607,$A4,'All Years'!C$2:C$607) -> 619 | D4: =SUMIF('All Years'!$B$2:$B$607,$A4,'All Years'!D$2:D$607) -> 284 | E4: =SUMIF('All Years'!$B$2:$B$607,$A4,'All Years'!E$2:E$607) -> 249 | F4: =SUMIF('All Years'!$B$2:$B$607,$A4,'All Years'!F$2:F$607) -> 1152 | G4: =SUMIF('All Years'!$B$2:$B$607,$A4,'All Years'!G$2:G$607) -> 2017 | H4: =SUMIF('All Years'!$B$2:$B$607,$A4,'All Years'!H$2:H$607) -> 1148 | I4: =SUMIF('All Years'!$B$2:$B$607,$A4,'All Years'!I$2:I$607) -> 869 | J4: =SUMIF('All Years'!$B$2:$B$607,$A4,'All Years'!J$2:J$607) -> 2141 | K4: 2
A5: Chelsea | B5: =COUNTIF('All Years'!$B$2:$B$607,A5) -> 30 | C5: =SUMIF('All Years'!$B$2:$B$607,$A5,'All Years'!C$2:C$607) -> 618 | D5: =SUMIF('All Years'!$B$2:$B$607,$A5,'All Years'!D$2:D$607) -> 284 | E5: =SUMIF('All Years'!$B$2:$B$607,$A5,'All Years'!E$2:E$607) -> 250 | F5: =SUMIF('All Years'!$B$2:$B$607,$A5,'All Years'!F$2:F$607) -> 1152 | G5: =SUMIF('All Years'!$B$2:$B$607,$A5,'All Years'!G$2:G$607) -> 1973 | H5: =SUMIF('All Years'!$B$2:$B$607,$A5,'All Years'!H$2:H$607) -> 1125 | I5: =SUMIF('All Years'!$B$2:$B$607,$A5,'All Years'!I$2:I$607) -> 848 | J5: =SUMIF('All Years'!$B$2:$B$607,$A5,'All Years'!J$2:J$607) -> 2138 | K5: 3
A6: Liverpool | B6: =COUNTIF('All Years'!$B$2:$B$607,A6) -> 30 | C6: =SUMIF('All Years'!$B$2:$B$607,$A6,'All Years'!C$2:C$607) -> 609 | D6: =SUMIF('All Years'!$B$2:$B$607,$A6,'All Years'!D$2:D$607) -> 282 | E6: =SUMIF('All Years'!$B$2:$B$607,$A6,'All Years'!E$2:E$607) -> 261 | F6: =SUMIF('All Years'!$B$2:$B$607,$A6,'All Years'!F$2:F$607) -> 1152 | G6: =SUMIF('All Years'!$B$2:$B$607,$A6,'All Years'!G$2:G$607) -> 2021 | H6: =SUMIF('All Years'!$B$2:$B$607,$A6,'All Years'!H$2:H$607) -> 1147 | I6: =SUMIF('All Years'!$B$2:$B$607,$A6,'All Years'!I$2:I$607) -> 874 | J6: =SUMIF('All Years'!$B$2:$B$607,$A6,'All Years'!J$2:J$607) -> 2109 | K6: 4
A7: Tottenham | B7: =COUNTIF('All Years'!$B$2:$B$607,A7) -> 30 | C7: =SUMIF('All Years'!$B$2:$B$607,$A7,'All Years'!C$2:C$607) -> 501 | D7: =SUMIF('All Years'!$B$2:$B$607,$A7,'All Years'!D$2:D$607) -> 281 | E7: =SUMIF('All Years'!$B$2:$B$607,$A7,'All Years'!E$2:E$607) -> 369 | F7: =SUMIF('All Years'!$B$2:$B$607,$A7,'All Years'!F$2:F$607) -> 1151 | G7: =SUMIF('All Years'!$B$2:$B$607,$A7,'All Years'!G$2:G$607) -> 1744 | H7: =SUMIF('All Years'!$B$2:$B$607,$A7,'All Years'!H$2:H$607) -> 1438 | I7: =SUMIF('All Years'!$B$2:$B$607,$A7,'All Years'!I$2:I$607) -> 306 | J7: =SUMIF('All Years'!$B$2:$B$607,$A7,'All Years'!J$2:J$607) -> 1784 | K7: 5
A8: Manchester City | B8: =COUNTIF('All Years'!$B$2:$B$607,A8) -> 25 | C8: =SUMIF('All Years'!$B$2:$B$607,$A8,'All Years'!C$2:C$607) -> 473 | D8: =SUMIF('All Years'!$B$2:$B$607,$A8,'All Years'!D$2:D$607) -> 210 | E8: =SUMIF('All Years'!$B$2:$B$607,$A8,'All Years'!E$2:E$607) -> 279 | F8: =SUMIF('All Years'!$B$2:$B$607,$A8,'All Years'!F$2:F$607) -> 962 | G8: =SUMIF('All Years'!$B$2:$B$607,$A8,'All Years'!G$2:G$607) -> 1658 | H8: =SUMIF('All Years'!$B$2:$B$607,$A8,'All Years'!H$2:H$607) -> 1068 | I8: =SUMIF('All Years'!$B$2:$B$607,$A8,'All Years'!I$2:I$607) -> 590 | J8: =SUMIF('All Years'!$B$2:$B$607,$A8,'All Years'!J$2:J$607) -> 1629 | K8: 6
A9: Everton | B9: =COUNTIF('All Years'!$B$2:$B$607,A9) -> 30 | C9: =SUMIF('All Years'!$B$2:$B$607,$A9,'All Years'!C$2:C$607) -> 418 | D9: =SUMIF('All Years'!$B$2:$B$607,$A9,'All Years'!D$2:D$607) -> 320 | E9: =SUMIF('All Years'!$B$2:$B$607,$A9,'All Years'!E$2:E$607) -> 414 | F9: =SUMIF('All Years'!$B$2:$B$607,$A9,'All Years'!F$2:F$607) -> 1152 | G9: =SUMIF('All Years'!$B$2:$B$607,$A9,'All Years'!G$2:G$607) -> 1491 | H9: =SUMIF('All Years'!$B$2:$B$607,$A9,'All Years'!H$2:H$607) -> 1481 | I9: =SUMIF('All Years'!$B$2:$B$607,$A9,'All Years'!I$2:I$607) -> 10 | J9: =SUMIF('All Years'!$B$2:$B$607,$A9,'All Years'!J$2:J$607) -> 1574 | K9: 7
A10: Newcastle | B10: =COUNTIF('All Years'!$B$2:$B$607,A10) -> 27 | C10: =SUMIF('All Years'!$B$2:$B$607,$A10,'All Years'!C$2:C$607) -> 382 | D10: =SUMIF('All Years'!$B$2:$B$607,$A10,'All Years'!D$2:D$607) -> 264 | E10: =SUMIF('All Years'!$B$2:$B$607,$A10,'All Years'!E$2:E$607) -> 388 | F10: =SUMIF('All Years'!$B$2:$B$607,$A10,'All Years'!F$2:F$607) -> 1034 | G10: =SUMIF('All Years'!$B$2:$B$607,$A10,'All Years'!G$2:G$607) -> 1377 | H10: =SUMIF('All Years'!$B$2:$B$607,$A10,'All Years'!H$2:H$607) -> 1417 | I10: =SUMIF('All Years'!$B$2:$B$607,$A10,'All Years'!I$2:I$607) -> -40 | J10: =SUMIF('All Years'!$B$2:$B$607,$A10,'All Years'!J$2:J$607) -> 1410 | K10: 8
A11: Aston Villa | B11: =COUNTIF('All Years'!$B$2:$B$607,A11) -> 27 | C11: =SUMIF('All Years'!$B$2:$B$607,$A11,'All Years'!C$2:C$607) -> 354 | D11: =SUMIF('All Years'!$B$2:$B$607,$A11,'All Years'!D$2:D$607) -> 296 | E11: =SUMIF('All Years'!$B$2:$B$607,$A11,'All Years'!E$2:E$607) -> 388 | F11: =SUMIF('All Years'!$B$2:$B$607,$A11,'All Years'!F$2:F$607) -> 1038 | G11: =SUMIF('All Years'!$B$2:$B$607,$A11,'All Years'!G$2:G$607) -> 1265 | H11: =SUMIF('All Years'!$B$2:$B$607,$A11,'All Years'!H$2:H$607) -> 1353 | I11: =SUMIF('All Years'!$B$2:$B$607,$A11,'All Years'!I$2:I$607) -> -88 | J11: =SUMIF('All Years'!$B$2:$B$607,$A11,'All Years'!J$2:J$607) -> 1358 | K11: 9
A12: West Ham | B12: =COUNTIF('All Years'!$B$2:$B$607,A12) -> 26 | C12: =SUMIF('All Years'!$B$2:$B$607,$A12,'All Years'!C$2:C$607) -> 335 | D12: =SUMIF('All Years'!$B$2:$B$607,$A12,'All Years'!D$2:D$607) -> 253 | E12: =SUMIF('All Years'!$B$2:$B$607,$A12,'All Years'!E$2:E$607) -> 408 | F12: =SUMIF('All Years'!$B$2:$B$607,$A12,'All Years'!F$2:F$607) -> 996 | G12: =SUMIF('All Years'!$B$2:$B$607,$A12,'All Years'!G$2:G$607) -> 1235 | H12: =SUMIF('All Years'!$B$2:$B$607,$A12,'All Years'!H$2:H$607) -> 1429 | I12: =SUMIF('All Years'!$B$2:$B$607,$A12,'All Years'!I$2:I$607) -> -194 | J12: =SUMIF('All Years'!$B$2:$B$607,$A12,'All Years'!J$2:J$607) -> 1258 | K12: 10
A13: Southampton | B13: =COUNTIF('All Years'!$B$2:$B$607,A13) -> 23 | C13: =SUMIF('All Years'!$B$2:$B$607,$A13,'All Years'!C$2:C$607) -> 274 | D13: =SUMIF('All Years'!$B$2:$B$607,$A13,'All Years'!D$2:D$607) -> 241 | E13: =SUMIF('All Years'!$B$2:$B$607,$A13,'All Years'!E$2:E$607) -> 371 | F13: =SUMIF('All Years'!$B$2:$B$607,$A13,'All Years'!F$2:F$607) -> 886 | G13: =SUMIF('All Years'!$B$2:$B$607,$A13,'All Years'!G$2:G$607) -> 1078 | H13: =SUMIF('All Years'!$B$2:$B$607,$A13,'All Years'!H$2:H$607) -> 1282 | I13: =SUMIF('All Years'!$B$2:$B$607,$A13,'All Years'!I$2:I$607) -> -204 | J13: =SUMIF('All Years'!$B$2:$B$607,$A13,'All Years'!J$2:J$607) -> 1063 | K13: 11
A14: Blackburn | B14: =COUNTIF('All Years'!$B$2:$B$607,A14) -> 18 | C14: =SUMIF('All Years'!$B$2:$B$607,$A14,'All Years'!C$2:C$607) -> 262 | D14: =SUMIF('All Years'!$B$2:$B$607,$A14,'All Years'!D$2:D$607) -> 184 | E14: =SUMIF('All Years'!$B$2:$B$607,$A14,'All Years'!E$2:E$607) -> 250 | F14: =SUMIF('All Years'!$B$2:$B$607,$A14,'All Years'!F$2:F$607) -> 696 | G14: =SUMIF('All Years'!$B$2:$B$607,$A14,'All Years'!G$2:G$607) -> 927 | H14: =SUMIF('All Years'!$B$2:$B$607,$A14,'All Years'!H$2:H$607) -> 907 | I14: =SUMIF('All Years'!$B$2:$B$607,$A14,'All Years'!I$2:I$607) -> 20 | J14: =SUMIF('All Years'!$B$2:$B$607,$A14,'All Years'!J$2:J$607) -> 970 | K14: 12
... A52: Swindon | B52: =COUNTIF('All Years'!$B$2:$B$607,A52) -> 1 | C52: =SUMIF('All Years'!$B$2:$B$607,$A52,'All Years'!C$2:C$607) -> 5 | D52: =SUMIF('All Years'!$B$2:$B$607,$A52,'All Years'!D$2:D$607) -> 15 | E52: =SUMIF('All Years'!$B$2:$B$607,$A52,'All Years'!E$2:E$607) -> 22 | F52: =SUMIF('All Years'!$B$2:$B$607,$A52,'All Years'!F$2:F$607) -> 42 | G52: =SUMIF('All Years'!$B$2:$B$607,$A52,'All Years'!G$2:G$607) -> 47 | H52: =SUMIF('All Years'!$B$2:$B$607,$A52,'All Years'!H$2:H$607) -> 100 | I52: =SUMIF('All Years'!$B$2:$B$607,$A52,'All Years'!I$2:I$607) -> -53 | J52: =SUMIF('All Years'!$B$2:$B$607,$A52,'All Years'!J$2:J$607) -> 30 | K52: 50

Sheet All Time Average
C1: AVERAGE PER SEASON
A2: Team | B2: Seasons | C2: Wins | D2: Draws | E2: Losses | F2: Games Played | G2: Goals For | H2: Goals Against | I2: Goal Difference | J2: Points | K2: Position
A3: Manchester United | B3: =COUNTIF('All Years'!$B$2:$B$607,A3) -> 30 | C3: ='All Time Table'!C3/'All Time Table'!$B3 -> 23.433333 | D3: ='All Time Table'!D3/'All Time Table'!$B3 -> 8.5666667 | E3: ='All Time Table'!E3/'All Time Table'!$B3 -> 6.4 | F3: ='All Time Table'!F3/'All Time Table'!$B3 -> 38.4 | G3: ='All Time Table'!G3/'All Time Table'!$B3 -> 72.833333 | H3: ='All Time Table'!H3/'All Time Table'!$B3 -> 35.533333 | I3: ='All Time Table'!I3/'All Time Table'!$B3 -> 37.3 | J3: ='All Time Table'!J3/'All Time Table'!$B3 -> 78.866667 | K3: 1
A4: Arsenal | B4: =COUNTIF('All Years'!$B$2:$B$607,A4) -> 30 | C4: ='All Time Table'!C4/'All Time Table'!$B4 -> 20.633333 | D4: ='All Time Table'!D4/'All Time Table'!$B4 -> 9.4666667 | E4: ='All Time Table'!E4/'All Time Table'!$B4 -> 8.3 | F4: ='All Time Table'!F4/'All Time Table'!$B4 -> 38.4 | G4: ='All Time Table'!G4/'All Time Table'!$B4 -> 67.233333 | H4: ='All Time Table'!H4/'All Time Table'!$B4 -> 38.266667 | I4: ='All Time Table'!I4/'All Time Table'!$B4 -> 28.966667 | J4: ='All Time Table'!J4/'All Time Table'!$B4 -> 71.366667 | K4: 2
A5: Chelsea | B5: =COUNTIF('All Years'!$B$2:$B$607,A5) -> 30 | C5: ='All Time Table'!C5/'All Time Table'!$B5 -> 20.6 | D5: ='All Time Table'!D5/'All Time Table'!$B5 -> 9.4666667 | E5: ='All Time Table'!E5/'All Time Table'!$B5 -> 8.3333333 | F5: ='All Time Table'!F5/'All Time Table'!$B5 -> 38.4 | G5: ='All Time Table'!G5/'All Time Table'!$B5 -> 65.766667 | H5: ='All Time Table'!H5/'All Time Table'!$B5 -> 37.5 | I5: ='All Time Table'!I5/'All Time Table'!$B5 -> 28.266667 | J5: ='All Time Table'!J5/'All Time Table'!$B5 -> 71.266667 | K5: 3
A6: Liverpool | B6: =COUNTIF('All Years'!$B$2:$B$607,A6) -> 30 | C6: ='All Time Table'!C6/'All Time Table'!$B6 -> 20.3 | D6: ='All Time Table'!D6/'All Time Table'!$B6 -> 9.4 | E6: ='All Time Table'!E6/'All Time Table'!$B6 -> 8.7 | F6: ='All Time Table'!F6/'All Time Table'!$B6 -> 38.4 | G6: ='All Time Table'!G6/'All Time Table'!$B6 -> 67.366667 | H6: ='All Time Table'!H6/'All Time Table'!$B6 -> 38.233333 | I6: ='All Time Table'!I6/'All Time Table'!$B6 -> 29.133333 | J6: ='All Time Table'!J6/'All Time Table'!$B6 -> 70.3 | K6: 4
A7: Manchester City | B7: =COUNTIF('All Years'!$B$2:$B$607,A7) -> 25 | C7: ='All Time Table'!C8/'All Time Table'!$B8 -> 18.92 | D7: ='All Time Table'!D8/'All Time Table'!$B8 -> 8.4 | E7: ='All Time Table'!E8/'All Time Table'!$B8 -> 11.16 | F7: ='All Time Table'!F8/'All Time Table'!$B8 -> 38.48 | G7: ='All Time Table'!G8/'All Time Table'!$B8 -> 66.32 | H7: ='All Time Table'!H8/'All Time Table'!$B8 -> 42.72 | I7: ='All Time Table'!I8/'All Time Table'!$B8 -> 23.6 | J7: ='All Time Table'!J8/'All Time Table'!$B8 -> 65.16 | K7: 5
A8: Tottenham | B8: =COUNTIF('All Years'!$B$2:$B$607,A8) -> 30 | C8: ='All Time Table'!C7/'All Time Table'!$B7 -> 16.7 | D8: ='All Time Table'!D7/'All Time Table'!$B7 -> 9.3666667 | E8: ='All Time Table'!E7/'All Time Table'!$B7 -> 12.3 | F8: ='All Time Table'!F7/'All Time Table'!$B7 -> 38.366667 | G8: ='All Time Table'!G7/'All Time Table'!$B7 -> 58.133333 | H8: ='All Time Table'!H7/'All Time Table'!$B7 -> 47.933333 | I8: ='All Time Table'!I7/'All Time Table'!$B7 -> 10.2 | J8: ='All Time Table'!J7/'All Time Table'!$B7 -> 59.466667 | K8: 6
A9: Leeds | B9: =COUNTIF('All Years'!$B$2:$B$607,A9) -> 14 | C9: ='All Time Table'!C15/'All Time Table'!$B15 -> 15.428571 | D9: ='All Time Table'!D15/'All Time Table'!$B15 -> 10.071429 | E9: ='All Time Table'!E15/'All Time Table'!$B15 -> 13.357143 | F9: ='All Time Table'!F15/'All Time Table'!$B15 -> 38.857143 | G9: ='All Time Table'!G15/'All Time Table'!$B15 -> 53.214286 | H9: ='All Time Table'!H15/'All Time Table'!$B15 -> 50.428571 | I9: ='All Time Table'!I15/'All Time Table'!$B15 -> 2.7857143 | J9: ='All Time Table'!J15/'All Time Table'!$B15 -> 56.357143 | K9: 7
A10: Blackburn | B10: =COUNTIF('All Years'!$B$2:$B$607,A10) -> 18 | C10: ='All Time Table'!C14/'All Time Table'!$B14 -> 14.555556 | D10: ='All Time Table'!D14/'All Time Table'!$B14 -> 10.222222 | E10: ='All Time Table'!E14/'All Time Table'!$B14 -> 13.888889 | F10: ='All Time Table'!F14/'All Time Table'!$B14 -> 38.666667 | G10: ='All Time Table'!G14/'All Time Table'!$B14 -> 51.5 | H10: ='All Time Table'!H14/'All Time Table'!$B14 -> 50.388889 | I10: ='All Time Table'!I14/'All Time Table'!$B14 -> 1.1111111 | J10: ='All Time Table'!J14/'All Time Table'!$B14 -> 53.888889 | K10: 8
A11: Everton | B11: =COUNTIF('All Years'!$B$2:$B$607,A11) -> 30 | C11: ='All Time Table'!C9/'All Time Table'!$B9 -> 13.933333 | D11: ='All Time Table'!D9/'All Time Table'!$B9 -> 10.666667 | E11: ='All Time Table'!E9/'All Time Table'!$B9 -> 13.8 | F11: ='All Time Table'!F9/'All Time Table'!$B9 -> 38.4 | G11: ='All Time Table'!G9/'All Time Table'!$B9 -> 49.7 | H11: ='All Time Table'!H9/'All Time Table'!$B9 -> 49.366667 | I11: ='All Time Table'!I9/'All Time Table'!$B9 -> 0.33333333 | J11: ='All Time Table'!J9/'All Time Table'!$B9 -> 52.466667 | K11: 9
A12: Newcastle | B12: =COUNTIF('All Years'!$B$2:$B$607,A12) -> 27 | C12: ='All Time Table'!C10/'All Time Table'!$B10 -> 14.148148 | D12: ='All Time Table'!D10/'All Time Table'!$B10 -> 9.7777778 | E12: ='All Time Table'!E10/'All Time Table'!$B10 -> 14.37037 | F12: ='All Time Table'!F10/'All Time Table'!$B10 -> 38.296296 | G12: ='All Time Table'!G10/'All Time Table'!$B10 -> 51 | H12: ='All Time Table'!H10/'All Time Table'!$B10 -> 52.481481 | I12: ='All Time Table'!I10/'All Time Table'!$B10 -> -1.4814815 | J12: ='All Time Table'!J10/'All Time Table'!$B10 -> 52.222222 | K12: 10
A13: Aston Villa | B13: =COUNTIF('All Years'!$B$2:$B$607,A13) -> 27 | C13: ='All Time Table'!C11/'All Time Table'!$B11 -> 13.111111 | D13: ='All Time Table'!D11/'All Time Table'!$B11 -> 10.962963 | E13: ='All Time Table'!E11/'All Time Table'!$B11 -> 14.37037 | F13: ='All Time Table'!F11/'All Time Table'!$B11 -> 38.444444 | G13: ='All Time Table'!G11/'All Time Table'!$B11 -> 46.851852 | H13: ='All Time Table'!H11/'All Time Table'!$B11 -> 50.111111 | I13: ='All Time Table'!I11/'All Time Table'!$B11 -> -3.2592593 | J13: ='All Time Table'!J11/'All Time Table'!$B11 -> 50.296296 | K13: 11
A14: Leicester | B14: =COUNTIF('All Years'!$B$2:$B$607,A14) -> 16 | C14: ='All Time Table'!C16/'All Time Table'!$B16 -> 13.0625 | D14: ='All Time Table'!D16/'All Time Table'!$B16 -> 10 | E14: ='All Time Table'!E16/'All Time Table'!$B16 -> 15.1875 | F14: ='All Time Table'!F16/'All Time Table'!$B16 -> 38.25 | G14: ='All Time Table'!G16/'All Time Table'!$B16 -> 51.25 | H14: ='All Time Table'!H16/'All Time Table'!$B16 -> 54.25 | I14: ='All Time Table'!I16/'All Time Table'!$B16 -> -3 | J14: ='All Time Table'!J16/'All Time Table'!$B16 -> 49.1875 | K14: 12
A15: Sheffield Weds | B15: =COUNTIF('All Years'!$B$2:$B$607,A15) -> 8 | C15: ='All Time Table'!C26/'All Time Table'!$B26 -> 12.625 | D15: ='All Time Table'!D26/'All Time Table'!$B26 -> 11.125 | E15: ='All Time Table'!E26/'All Time Table'!$B26 -> 15.75 | F15: ='All Time Table'!F26/'All Time Table'!$B26 -> 39.5 | G15: ='All Time Table'!G26/'All Time Table'!$B26 -> 51.125 | H15: ='All Time Table'!H26/'All Time Table'!$B26 -> 56.625 | I15: ='All Time Table'!I26/'All Time Table'!$B26 -> -5.5 | J15: ='All Time Table'!J26/'All Time Table'!$B26 -> 49 | K15: 13
A16: Wimbledon FC | B16: =COUNTIF('All Years'!$B$2:$B$607,A16) -> 8 | C16: ='All Time Table'!C27/'All Time Table'!$B27 -> 12.375 | D16: ='All Time Table'!D27/'All Time Table'!$B27 -> 11.75 | E16: ='All Time Table'!E27/'All Time Table'!$B27 -> 15.375 | F16: ='All Time Table'!F27/'All Time Table'!$B27 -> 39.5 | G16: ='All Time Table'!G27/'All Time Table'!$B27 -> 48 | H16: ='All Time Table'!H27/'All Time Table'!$B27 -> 59 | I16: ='All Time Table'!I27/'All Time Table'!$B27 -> -11 | J16: ='All Time Table'!J27/'All Time Table'!$B27 -> 48.875 | K16: 14
A17: West Ham | B17: =COUNTIF('All Years'!$B$2:$B$607,A17) -> 26 | C17: ='All Time Table'!C12/'All Time Table'!$B12 -> 12.884615 | D17: ='All Time Table'!D12/'All Time Table'!$B12 -> 9.7307692 | E17: ='All Time Table'!E12/'All Time Table'!$B12 -> 15.692308 | F17: ='All Time Table'!F12/'All Time Table'!$B12 -> 38.307692 | G17: ='All Time Table'!G12/'All Time Table'!$B12 -> 47.5 | H17: ='All Time Table'!H12/'All Time Table'!$B12 -> 54.961538 | I17: ='All Time Table'!I12/'All Time Table'!$B12 -> -7.4615385 | J17: ='All Time Table'!J12/'All Time Table'!$B12 -> 48.384615 | K17: 15
A18: Nottingham Forest | B18: =COUNTIF('All Years'!$B$2:$B$607,A18) -> 5 | C18: ='All Time Table'!C38/'All Time Table'!$B38 -> 12 | D18: ='All Time Table'!D38/'All Time Table'!$B38 -> 11.8 | E18: ='All Time Table'!E38/'All Time Table'!$B38 -> 15.8 | F18: ='All Time Table'!F38/'All Time Table'!$B38 -> 39.6 | G18: ='All Time Table'!G38/'All Time Table'!$B38 -> 45.8 | H18: ='All Time Table'!H38/'All Time Table'!$B38 -> 57.4 | I18: ='All Time Table'!I38/'All Time Table'!$B38 -> -11.6 | J18: ='All Time Table'!J38/'All Time Table'!$B38 -> 47.8 | K18: 16
A19: Southampton | B19: =COUNTIF('All Years'!$B$2:$B$607,A19) -> 23 | C19: ='All Time Table'!C13/'All Time Table'!$B13 -> 11.913043 | D19: ='All Time Table'!D13/'All Time Table'!$B13 -> 10.478261 | E19: ='All Time Table'!E13/'All Time Table'!$B13 -> 16.130435 | F19: ='All Time Table'!F13/'All Time Table'!$B13 -> 38.521739 | G19: ='All Time Table'!G13/'All Time Table'!$B13 -> 46.869565 | H19: ='All Time Table'!H13/'All Time Table'!$B13 -> 55.73913 | I19: ='All Time Table'!I13/'All Time Table'!$B13 -> -8.8695652 | J19: ='All Time Table'!J13/'All Time Table'!$B13 -> 46.217391 | K19: 17
A20: Brentford | B20: =COUNTIF('All Years'!$B$2:$B$607,A20) -> 1 | C20: ='All Time Table'!C49/'All Time Table'!$B49 -> 13 | D20: ='All Time Table'!D49/'All Time Table'!$B49 -> 7 | E20: ='All Time Table'!E49/'All Time Table'!$B49 -> 18 | F20: ='All Time Table'!F49/'All Time Table'!$B49 -> 38 | G20: ='All Time Table'!G49/'All Time Table'!$B49 -> 48 | H20: ='All Time Table'!H49/'All Time Table'!$B49 -> 56 | I20: ='All Time Table'!I49/'All Time Table'!$B49 -> -8 | J20: ='All Time Table'!J49/'All Time Table'!$B49 -> 46 | K20: 18
A21: Stoke City | B21: =COUNTIF('All Years'!$B$2:$B$607,A21) -> 10 | C21: ='All Time Table'!C23/'All Time Table'!$B23 -> 11.6 | D21: ='All Time Table'!D23/'All Time Table'!$B23 -> 10.9 | E21: ='All Time Table'!E23/'All Time Table'!$B23 -> 15.5 | F21: ='All Time Table'!F23/'All Time Table'!$B23 -> 38 | G21: ='All Time Table'!G23/'All Time Table'!$B23 -> 39.8 | H21: ='All Time Table'!H23/'All Time Table'!$B23 -> 52.5 | I21: ='All Time Table'!I23/'All Time Table'!$B23 -> -12.7 | J21: ='All Time Table'!J23/'All Time Table'!$B23 -> 45.7 | K21: 19
A22: Coventry | B22: =COUNTIF('All Years'!$B$2:$B$607,A22) -> 9 | C22: ='All Time Table'!C24/'All Time Table'!$B24 -> 11 | D22: ='All Time Table'!D24/'All Time Table'!$B24 -> 12.444444 | E22: ='All Time Table'!E24/'All Time Table'!$B24 -> 15.888889 | F22: ='All Time Table'!F24/'All Time Table'!$B24 -> 39.333333 | G22: ='All Time Table'!G24/'All Time Table'!$B24 -> 43 | H22: ='All Time Table'!H24/'All Time Table'!$B24 -> 54.444444 | I22: ='All Time Table'!I24/'All Time Table'!$B24 -> -11.444444 | J22: ='All Time Table'!J24/'All Time Table'!$B24 -> 45.444444 | K22: 20
A23: Charlton | B23: =COUNTIF('All Years'!$B$2:$B$607,A23) -> 8 | C23: ='All Time Table'!C28/'All Time Table'!$B28 -> 11.625 | D23: ='All Time Table'!D28/'All Time Table'!$B28 -> 10.25 | E23: ='All Time Table'!E28/'All Time Table'!$B28 -> 16.125 | F23: ='All Time Table'!F28/'All Time Table'!$B28 -> 38 | G23: ='All Time Table'!G28/'All Time Table'!$B28 -> 42.75 | H23: ='All Time Table'!H28/'All Time Table'!$B28 -> 55.25 | I23: ='All Time Table'!I28/'All Time Table'!$B28 -> -12.5 | J23: ='All Time Table'!J28/'All Time Table'!$B28 -> 45.125 | K23: 21
A24: Ipswich | B24: =COUNTIF('All Years'!$B$2:$B$607,A24) -> 5 | C24: ='All Time Table'!C39/'All Time Table'!$B39 -> 11.4 | D24: ='All Time Table'!D39/'All Time Table'!$B39 -> 10.6 | E24: ='All Time Table'!E39/'All Time Table'!$B39 -> 18.4 | F24: ='All Time Table'!F39/'All Time Table'!$B39 -> 40.4 | G24: ='All Time Table'!G39/'All Time Table'!$B39 -> 43.8 | H24: ='All Time Table'!H39/'All Time Table'!$B39 -> 62.4 | I24: ='All Time Table'!I39/'All Time Table'!$B39 -> -18.6 | J24: ='All Time Table'!J39/'All Time Table'!$B39 -> 44.8 | K24: 22
A25: Swansea | B25: =COUNTIF('All Years'!$B$2:$B$607,A25) -> 7 | C25: ='All Time Table'!C32/'All Time Table'!$B32 -> 11.714286 | D25: ='All Time Table'!D32/'All Time Table'!$B32 -> 9.4285714 | E25: ='All Time Table'!E32/'All Time Table'!$B32 -> 16.857143 | F25: ='All Time Table'!F32/'All Time Table'!$B32 -> 38 | G25: ='All Time Table'!G32/'All Time Table'!$B32 -> 43.714286 | H25: ='All Time Table'!H32/'All Time Table'!$B32 -> 54.714286 | I25: ='All Time Table'!I32/'All Time Table'!$B32 -> -11 | J25: ='All Time Table'!J32/'All Time Table'!$B32 -> 44.571429 | K25: 23
A26: Oldham | B26: =COUNTIF('All Years'!$B$2:$B$607,A26) -> 2 | C26: ='All Time Table'!C45/'All Time Table'!$B45 -> 11 | D26: ='All Time Table'!D45/'All Time Table'!$B45 -> 11.5 | E26: ='All Time Table'!E45/'All Time Table'!$B45 -> 19.5 | F26: ='All Time Table'!F45/'All Time Table'!$B45 -> 42 | G26: ='All Time Table'!G45/'All Time Table'!$B45 -> 52.5 | H26: ='All Time Table'!H45/'All Time Table'!$B45 -> 71 | I26: ='All Time Table'!I45/'All Time Table'!$B45 -> -18.5 | J26: ='All Time Table'!J45/'All Time Table'!$B45 -> 44.5 | K26: 24
A27: Middlesbrough | B27: =COUNTIF('All Years'!$B$2:$B$607,A27) -> 15 | C27: ='All Time Table'!C17/'All Time Table'!$B17 -> 11 | D27: ='All Time Table'!D17/'All Time Table'!$B17 -> 11.266667 | E27: ='All Time Table'!E17/'All Time Table'!$B17 -> 16 | F27: ='All Time Table'!F17/'All Time Table'!$B17 -> 38.266667 | G27: ='All Time Table'!G17/'All Time Table'!$B17 -> 43.2 | H27: ='All Time Table'!H17/'All Time Table'!$B17 -> 52.933333 | I27: ='All Time Table'!I17/'All Time Table'!$B17 -> -9.7333333 | J27: ='All Time Table'!J17/'All Time Table'!$B17 -> 44.266667 | K27: 25
A28: Bolton | B28: =COUNTIF('All Years'!$B$2:$B$607,A28) -> 13 | C28: ='All Time Table'!C20/'All Time Table'!$B20 -> 11.461538 | D28: ='All Time Table'!D20/'All Time Table'!$B20 -> 9.8461538 | E28: ='All Time Table'!E20/'All Time Table'!$B20 -> 16.692308 | F28: ='All Time Table'!F20/'All Time Table'!$B20 -> 38 | G28: ='All Time Table'!G20/'All Time Table'!$B20 -> 44.230769 | H28: ='All Time Table'!H20/'All Time Table'!$B20 -> 57.307692 | I28: ='All Time Table'!I20/'All Time Table'!$B20 -> -13.076923 | J28: ='All Time Table'!J20/'All Time Table'!$B20 -> 44.230769 | K28: 26
A29: QPR | B29: =COUNTIF('All Years'!$B$2:$B$607,A29) -> 7 | C29: ='All Time Table'!C33/'All Time Table'!$B33 -> 11.571429 | D29: ='All Time Table'!D33/'All Time Table'!$B33 -> 9.2857143 | E29: ='All Time Table'!E33/'All Time Table'!$B33 -> 18.857143 | F29: ='All Time Table'!F33/'All Time Table'!$B33 -> 39.714286 | G29: ='All Time Table'!G33/'All Time Table'!$B33 -> 48.428571 | H29: ='All Time Table'!H33/'All Time Table'!$B33 -> 61.571429 | I29: ='All Time Table'!I33/'All Time Table'!$B33 -> -13.142857 | J29: ='All Time Table'!J33/'All Time Table'!$B33 -> 44 | K29: 27
A30: Wolves | B30: =COUNTIF('All Years'!$B$2:$B$607,A30) -> 8 | C30: ='All Time Table'!C29/'All Time Table'!$B29 -> 11.25 | D30: ='All Time Table'!D29/'All Time Table'!$B29 -> 9.75 | E30: ='All Time Table'!E29/'All Time Table'!$B29 -> 17 | F30: ='All Time Table'!F29/'All Time Table'!$B29 -> 38 | G30: ='All Time Table'!G29/'All Time Table'!$B29 -> 41 | H30: ='All Time Table'!H29/'All Time Table'!$B29 -> 57.75 | I30: ='All Time Table'!I29/'All Time Table'!$B29 -> -16.75 | J30: ='All Time Table'!J29/'All Time Table'!$B29 -> 43.5 | K30: 28
A31: Crystal Palace | B31: =COUNTIF('All Years'!$B$2:$B$607,A31) -> 13 | C31: ='All Time Table'!C21/'All Time Table'!$B21 -> 11.153846 | D31: ='All Time Table'!D21/'All Time Table'!$B21 -> 9.9230769 | E31: ='All Time Table'!E21/'All Time Table'!$B21 -> 17.538462 | F31: ='All Time Table'!F21/'All Time Table'!$B21 -> 38.615385 | G31: ='All Time Table'!G21/'All Time Table'!$B21 -> 42.076923 | H31: ='All Time Table'!H21/'All Time Table'!$B21 -> 55.846154 | I31: ='All Time Table'!I21/'All Time Table'!$B21 -> -13.769231 | J31: ='All Time Table'!J21/'All Time Table'!$B21 -> 43.384615 | K31: 29
A32: Portsmouth | B32: =COUNTIF('All Years'!$B$2:$B$607,A32) -> 7 | C32: ='All Time Table'!C34/'All Time Table'!$B34 -> 11.285714 | D32: ='All Time Table'!D34/'All Time Table'!$B34 -> 9.2857143 | E32: ='All Time Table'!E34/'All Time Table'!$B34 -> 17.428571 | F32: ='All Time Table'!F34/'All Time Table'!$B34 -> 38 | G32: ='All Time Table'!G34/'All Time Table'!$B34 -> 41.714286 | H32: ='All Time Table'!H34/'All Time Table'!$B34 -> 54.285714 | I32: ='All Time Table'!I34/'All Time Table'!$B34 -> -12.571429 | J32: ='All Time Table'!J34/'All Time Table'!$B34 -> 43.142857 | K32: 30
A33: Birmingham | B33: =COUNTIF('All Years'!$B$2:$B$607,A33) -> 7 | C33: ='All Time Table'!C35/'All Time Table'!$B35 -> 10.428571 | D33: ='All Time Table'!D35/'All Time Table'!$B35 -> 11.714286 | E33: ='All Time Table'!E35/'All Time Table'!$B35 -> 15.857143 | F33: ='All Time Table'!F35/'All Time Table'!$B35 -> 38 | G33: ='All Time Table'!G35/'All Time Table'!$B35 -> 39 | H33: ='All Time Table'!H35/'All Time Table'!$B35 -> 51.428571 | I33: ='All Time Table'!I35/'All Time Table'!$B35 -> -12.428571 | J33: ='All Time Table'!J35/'All Time Table'!$B35 -> 43 | K33: 31
A34: Fulham | B34: =COUNTIF('All Years'!$B$2:$B$607,A34) -> 15 | C34: ='All Time Table'!C18/'All Time Table'!$B18 -> 10.8 | D34: ='All Time Table'!D18/'All Time Table'!$B18 -> 10.266667 | E34: ='All Time Table'!E18/'All Time Table'!$B18 -> 16.933333 | F34: ='All Time Table'!F18/'All Time Table'!$B18 -> 38 | G34: ='All Time Table'!G18/'All Time Table'!$B18 -> 42.066667 | H34: ='All Time Table'!H18/'All Time Table'!$B18 -> 55.466667 | I34: ='All Time Table'!I18/'All Time Table'!$B18 -> -13.4 | J34: ='All Time Table'!J18/'All Time Table'!$B18 -> 42.666667 | K34: 32
A35: Bournemouth | B35: =COUNTIF('All Years'!$B$2:$B$607,A35) -> 5 | C35: ='All Time Table'!C40/'All Time Table'!$B40 -> 11.2 | D35: ='All Time Table'!D40/'All Time Table'!$B40 -> 8.6 | E35: ='All Time Table'!E40/'All Time Table'!$B40 -> 18.2 | F35: ='All Time Table'!F40/'All Time Table'!$B40 -> 38 | G35: ='All Time Table'!G40/'All Time Table'!$B40 -> 48.2 | H35: ='All Time Table'!H40/'All Time Table'!$B40 -> 66 | I35: ='All Time Table'!I40/'All Time Table'!$B40 -> -17.8 | J35: ='All Time Table'!J40/'All Time Table'!$B40 -> 42.2 | K35: 33
A36: Brighton | B36: =COUNTIF('All Years'!$B$2:$B$607,A36) -> 5 | C36: ='All Time Table'!C41/'All Time Table'!$B41 -> 9.6 | D36: ='All Time Table'!D41/'All Time Table'!$B41 -> 13 | E36: ='All Time Table'!E41/'All Time Table'!$B41 -> 15.4 | F36: ='All Time Table'!F41/'All Time Table'!$B41 -> 38 | G36: ='All Time Table'!G41/'All Time Table'!$B41 -> 38 | H36: ='All Time Table'!H41/'All Time Table'!$B41 -> 51.6 | I36: ='All Time Table'!I41/'All Time Table'!$B41 -> -13.6 | J36: ='All Time Table'!J41/'All Time Table'!$B41 -> 41.8 | K36: 34
A37: Sheffield United | B37: =COUNTIF('All Years'!$B$2:$B$607,A37) -> 5 | C37: ='All Time Table'!C42/'All Time Table'!$B42 -> 10.6 | D37: ='All Time Table'!D42/'All Time Table'!$B42 -> 10 | E37: ='All Time Table'!E42/'All Time Table'!$B42 -> 19 | F37: ='All Time Table'!F42/'All Time Table'!$B42 -> 39.6 | G37: ='All Time Table'!G42/'All Time Table'!$B42 -> 37.4 | H37: ='All Time Table'!H42/'All Time Table'!$B42 -> 54 | I37: ='All Time Table'!I42/'All Time Table'!$B42 -> -16.6 | J37: ='All Time Table'!J42/'All Time Table'!$B42 -> 41.8 | K37: 35
A38: Wigan | B38: =COUNTIF('All Years'!$B$2:$B$607,A38) -> 8 | C38: ='All Time Table'!C30/'All Time Table'!$B30 -> 10.625 | D38: ='All Time Table'!D30/'All Time Table'!$B30 -> 9.5 | E38: ='All Time Table'!E30/'All Time Table'!$B30 -> 17.875 | F38: ='All Time Table'!F30/'All Time Table'!$B30 -> 38 | G38: ='All Time Table'!G30/'All Time Table'!$B30 -> 39.5 | H38: ='All Time Table'!H30/'All Time Table'!$B30 -> 60.25 | I38: ='All Time Table'!I30/'All Time Table'!$B30 -> -20.75 | J38: ='All Time Table'!J30/'All Time Table'!$B30 -> 41.375 | K38: 36
A39: Burnley | B39: =COUNTIF('All Years'!$B$2:$B$607,A39) -> 8 | C39: ='All Time Table'!C31/'All Time Table'!$B31 -> 10.375 | D39: ='All Time Table'!D31/'All Time Table'!$B31 -> 9.5 | E39: ='All Time Table'!E31/'All Time Table'!$B31 -> 18.125 | F39: ='All Time Table'!F31/'All Time Table'!$B31 -> 38 | G39: ='All Time Table'!G31/'All Time Table'!$B31 -> 37.5 | H39: ='All Time Table'!H31/'All Time Table'!$B31 -> 56.875 | I39: ='All Time Table'!I31/'All Time Table'!$B31 -> -19.375 | J39: ='All Time Table'!J31/'All Time Table'!$B31 -> 40.625 | K39: 37
A40: Norwich | B40: =COUNTIF('All Years'!$B$2:$B$607,A40) -> 10 | C40: ='All Time Table'!C25/'All Time Table'!$B25 -> 9.9 | D40: ='All Time Table'!D25/'All Time Table'!$B25 -> 10.5 | E40: ='All Time Table'!E25/'All Time Table'!$B25 -> 18.8 | F40: ='All Time Table'!F25/'All Time Table'!$B25 -> 39.2 | G40: ='All Time Table'!G25/'All Time Table'!$B25 -> 41.4 | H40: ='All Time Table'!H25/'All Time Table'!$B25 -> 66.9 | I40: ='All Time Table'!I25/'All Time Table'!$B25 -> -25.5 | J40: ='All Time Table'!J25/'All Time Table'!$B25 -> 40.2 | K40: 38
...

Sheet All Years
A1: Season | B1: Team | C1: Wins | D1: Draws | E1: Losses | F1: Games Played | G1: Goals For | H1: Goals Against | I1: Goal Difference | J1: Points | K1: Position
A2: 1992-1993 | B2: ='1992-1993'!M2 -> Manchester United | C2: ='1992-1993'!N2 -> 24 | D2: ='1992-1993'!O2 -> 12 | E2: ='1992-1993'!P2 -> 6 | F2: ='1992-1993'!Q2 -> 42 | G2: ='1992-1993'!R2 -> 67 | H2: ='1992-1993'!S2 -> 31 | I2: ='1992-1993'!T2 -> 36 | ... K2: ='1992-1993'!V2 -> 1
A3: 1992-1993 | B3: ='1992-1993'!M3 -> Aston Villa | C3: ='1992-1993'!N3 -> 21 | D3: ='1992-1993'!O3 -> 11 | E3: ='1992-1993'!P3 -> 10 | F3: ='1992-1993'!Q3 -> 42 | G3: ='1992-1993'!R3 -> 57 | H3: ='1992-1993'!S3 -> 40 | I3: ='1992-1993'!T3 -> 17 | ... K3: ='1992-1993'!V3 -> 2
A4: 1992-1993 | B4: ='1992-1993'!M4 -> Norwich | C4: ='1992-1993'!N4 -> 21 | D4: ='1992-1993'!O4 -> 9 | E4: ='1992-1993'!P4 -> 12 | F4: ='1992-1993'!Q4 -> 42 | G4: ='1992-1993'!R4 -> 61 | H4: ='1992-1993'!S4 -> 65 | I4: ='1992-1993'!T4 -> -4 | ... K4: ='1992-1993'!V4 -> 3
A5: 1992-1993 | B5: ='1992-1993'!M5 -> Blackburn | C5: ='1992-1993'!N5 -> 20 | D5: ='1992-1993'!O5 -> 11 | E5: ='1992-1993'!P5 -> 11 | F5: ='1992-1993'!Q5 -> 42 | G5: ='1992-1993'!R5 -> 68 | H5: ='1992-1993'!S5 -> 46 | I5: ='1992-1993'!T5 -> 22 | ... K5: ='1992-1993'!V5 -> 4
A6: 1992-1993 | B6: ='1992-1993'!M6 -> QPR | C6: ='1992-1993'!N6 -> 17 | D6: ='1992-1993'!O6 -> 12 | E6: ='1992-1993'!P6 -> 13 | F6: ='1992-1993'!Q6 -> 42 | G6: ='1992-1993'!R6 -> 63 | H6: ='1992-1993'!S6 -> 55 | I6: ='1992-1993'!T6 -> 8 | ... K6: ='1992-1993'!V6 -> 5
A7: 1992-1993 | B7: ='1992-1993'!M7 -> Liverpool | C7: ='1992-1993'!N7 -> 16 | D7: ='1992-1993'!O7 -> 11 | E7: ='1992-1993'!P7 -> 15 | F7: ='1992-1993'!Q7 -> 42 | G7: ='1992-1993'!R7 -> 62 | H7: ='1992-1993'!S7 -> 55 | I7: ='1992-1993'!T7 -> 7 | ... K7: ='1992-1993'!V7 -> 6
A8: 1992-1993 | B8: ='1992-1993'!M8 -> Sheffield Weds | C8: ='1992-1993'!N8 -> 15 | D8: ='1992-1993'!O8 -> 14 | E8: ='1992-1993'!P8 -> 13 | F8: ='1992-1993'!Q8 -> 42 | G8: ='1992-1993'!R8 -> 55 | H8: ='1992-1993'!S8 -> 51 | I8: ='1992-1993'!T8 -> 4 | ... K8: ='1992-1993'!V8 -> 7
A9: 1992-1993 | B9: ='1992-1993'!M9 -> Tottenham | C9: ='1992-1993'!N9 -> 16 | D9: ='1992-1993'!O9 -> 11 | E9: ='1992-1993'!P9 -> 15 | F9: ='1992-1993'!Q9 -> 42 | G9: ='1992-1993'!R9 -> 60 | H9: ='1992-1993'!S9 -> 66 | I9: ='1992-1993'!T9 -> -6 | ... K9: ='1992-1993'!V9 -> 8
A10: 1992-1993 | B10: ='1992-1993'!M10 -> Manchester City | C10: ='1992-1993'!N10 -> 15 | D10: ='1992-1993'!O10 -> 12 | E10: ='1992-1993'!P10 -> 15 | F10: ='1992-1993'!Q10 -> 42 | G10: ='1992-1993'!R10 -> 56 | H10: ='1992-1993'!S10 -> 51 | I10: ='1992-1993'!T10 -> 5 | ... K10: ='1992-1993'!V10 -> 9
A11: 1992-1993 | B11: ='1992-1993'!M11 -> Arsenal | C11: ='1992-1993'!N11 -> 15 | D11: ='1992-1993'!O11 -> 11 | E11: ='1992-1993'!P11 -> 16 | F11: ='1992-1993'!Q11 -> 42 | G11: ='1992-1993'!R11 -> 40 | H11: ='1992-1993'!S11 -> 38 | I11: ='1992-1993'!T11 -> 2 | ... K11: ='1992-1993'!V11 -> 10
A12: 1992-1993 | B12: ='1992-1993'!M12 -> Chelsea | C12: ='1992-1993'!N12 -> 14 | D12: ='1992-1993'!O12 -> 14 | E12: ='1992-1993'!P12 -> 14 | F12: ='1992-1993'!Q12 -> 42 | G12: ='1992-1993'!R12 -> 51 | H12: ='1992-1993'!S12 -> 54 | I12: ='1992-1993'!T12 -> -3 | ... K12: ='1992-1993'!V12 -> 11
A13: 1992-1993 | B13: ='1992-1993'!M13 -> Wimbledon FC | C13: ='1992-1993'!N13 -> 14 | D13: ='1992-1993'!O13 -> 12 | E13: ='1992-1993'!P13 -> 16 | F13: ='1992-1993'!Q13 -> 42 | G13: ='1992-1993'!R13 -> 56 | H13: ='1992-1993'!S13 -> 55 | I13: ='1992-1993'!T13 -> 1 | ... K13: ='1992-1993'!V13 -> 12
... A23: 1992-1993 | B23: ='1992-1993'!M23 -> Nottingham Forest | C23: ='1992-1993'!N23 -> 10 | D23: ='1992-1993'!O23 -> 10 | E23: ='1992-1993'!P23 -> 22 | F23: ='1992-1993'!Q23 -> 42 | G23: ='1992-1993'!R23 -> 41 | H23: ='1992-1993'!S23 -> 62 | I23: ='1992-1993'!T23 -> -21 | ... K23: ='1992-1993'!V23 -> 22
A24: 1993-1994 | B24: ='1993-1994'!M2 -> Manchester United | C24: ='1993-1994'!N2 -> 27 | D24: ='1993-1994'!O2 -> 11 | E24: ='1993-1994'!P2 -> 4 | F24: ='1993-1994'!Q2 -> 42 | G24: ='1993-1994'!R2 -> 80 | H24: ='1993-1994'!S2 -> 38 | I24: ='1993-1994'!T2 -> 42 | ... K24: ='1993-1994'!V2 -> 1
A25: 1993-1994 | B25: ='1993-1994'!M3 -> Blackburn | C25: ='1993-1994'!N3 -> 25 | D25: ='1993-1994'!O3 -> 9 | E25: ='1993-1994'!P3 -> 8 | F25: ='1993-1994'!Q3 -> 42 | G25: ='1993-1994'!R3 -> 63 | H25: ='1993-1994'!S3 -> 36 | I25: ='1993-1994'!T3 -> 27 | ... K25: ='1993-1994'!V3 -> 2
A26: 1993-1994 | B26: ='1993-1994'!M4 -> Newcastle | C26: ='1993-1994'!N4 -> 23 | D26: ='1993-1994'!O4 -> 8 | E26: ='1993-1994'!P4 -> 11 | F26: ='1993-1994'!Q4 -> 42 | G26: ='1993-1994'!R4 -> 82 | H26: ='1993-1994'!S4 -> 41 | I26: ='1993-1994'!T4 -> 41 | ... K26: ='1993-1994'!V4 -> 3
A27: 1993-1994 | B27: ='1993-1994'!M5 -> Arsenal | C27: ='1993-1994'!N5 -> 18 | D27: ='1993-1994'!O5 -> 17 | E27: ='1993-1994'!P5 -> 7 | F27: ='1993-1994'!Q5 -> 42 | G27: ='1993-1994'!R5 -> 53 | H27: ='1993-1994'!S5 -> 28 | I27: ='1993-1994'!T5 -> 25 | ... K27: ='1993-1994'!V5 -> 4
A28: 1993-1994 | B28: ='1993-1994'!M6 -> Leeds | C28: ='1993-1994'!N6 -> 18 | D28: ='1993-1994'!O6 -> 16 | E28: ='1993-1994'!P6 -> 8 | F28: ='1993-1994'!Q6 -> 42 | G28: ='1993-1994'!R6 -> 65 | H28: ='1993-1994'!S6 -> 39 | I28: ='1993-1994'!T6 -> 26 | ... K28: ='1993-1994'!V6 -> 5
A29: 1993-1994 | B29: ='1993-1994'!M7 -> Wimbledon FC | C29: ='1993-1994'!N7 -> 18 | D29: ='1993-1994'!O7 -> 11 | E29: ='1993-1994'!P7 -> 13 | F29: ='1993-1994'!Q7 -> 42 | G29: ='1993-1994'!R7 -> 56 | H29: ='1993-1994'!S7 -> 53 | I29: ='1993-1994'!T7 -> 3 | ... K29: ='1993-1994'!V7 -> 6
A30: 1993-1994 | B30: ='1993-1994'!M8 -> Sheffield Weds | C30: ='1993-1994'!N8 -> 16 | D30: ='1993-1994'!O8 -> 16 | E30: ='1993-1994'!P8 -> 10 | F30: ='1993-1994'!Q8 -> 42 | G30: ='1993-1994'!R8 -> 76 | H30: ='1993-1994'!S8 -> 54 | I30: ='1993-1994'!T8 -> 22 | ... K30: ='1993-1994'!V8 -> 7
A31: 1993-1994 | B31: ='1993-1994'!M9 -> Liverpool | C31: ='1993-1994'!N9 -> 17 | D31: ='1993-1994'!O9 -> 9 | E31: ='1993-1994'!P9 -> 16 | F31: ='1993-1994'!Q9 -> 42 | G31: ='1993-1994'!R9 -> 59 | H31: ='1993-1994'!S9 -> 55 | I31: ='1993-1994'!T9 -> 4 | ... K31: ='1993-1994'!V9 -> 8
A32: 1993-1994 | B32: ='1993-1994'!M10 -> QPR | C32: ='1993-1994'!N10 -> 16 | D32: ='1993-1994'!O10 -> 12 | E32: ='1993-1994'!P10 -> 14 | F32: ='1993-1994'!Q10 -> 42 | G32: ='1993-1994'!R10 -> 62 | H32: ='1993-1994'!S10 -> 61 | I32: ='1993-1994'!T10 -> 1 | ... K32: ='1993-1994'!V10 -> 9
A33: 1993-1994 | B33: ='1993-1994'!M11 -> Aston Villa | C33: ='1993-1994'!N11 -> 15 | D33: ='1993-1994'!O11 -> 12 | E33: ='1993-1994'!P11 -> 15 | F33: ='1993-1994'!Q11 -> 42 | G33: ='1993-1994'!R11 -> 46 | H33: ='1993-1994'!S11 -> 50 | I33: ='1993-1994'!T11 -> -4 | ... K33: ='1993-1994'!V11 -> 10
A34: 1993-1994 | B34: ='1993-1994'!M12 -> Coventry | C34: ='1993-1994'!N12 -> 14 | D34: ='1993-1994'!O12 -> 14 | E34: ='1993-1994'!P12 -> 14 | F34: ='1993-1994'!Q12 -> 42 | G34: ='1993-1994'!R12 -> 43 | H34: ='1993-1994'!S12 -> 45 | I34: ='1993-1994'!T12 -> -2 | ... K34: ='1993-1994'!V12 -> 11
A35: 1993-1994 | B35: ='1993-1994'!M13 -> Norwich | C35: ='1993-1994'!N13 -> 12 | D35: ='1993-1994'!O13 -> 17 | E35: ='1993-1994'!P13 -> 13 | F35: ='1993-1994'!Q13 -> 42 | G35: ='1993-1994'!R13 -> 65 | H35: ='1993-1994'!S13 -> 61 | I35: ='1993-1994'!T13 -> 4 | ... K35: ='1993-1994'!V13 -> 12
... A45: 1993-1994 | B45: ='1993-1994'!M23 -> Swindon | C45: ='1993-1994'!N23 -> 5 | D45: ='1993-1994'!O23 -> 15 | E45: ='1993-1994'!P23 -> 22 | F45: ='1993-1994'!Q23 -> 42 | G45: ='1993-1994'!R23 -> 47 | H45: ='1993-1994'!S23 -> 100 | I45: ='1993-1994'!T23 -> -53 | ... K45: ='1993-1994'!V23 -> 22
A46: 1994-1995 | B46: ='1994-1995'!M2 -> Blackburn | C46: ='1994-1995'!N2 -> 27 | D46: ='1994-1995'!O2 -> 8 | E46: ='1994-1995'!P2 -> 7 | F46: ='1994-1995'!Q2 -> 42 | G46: ='1994-1995'!R2 -> 80 | H46: ='1994-1995'!S2 -> 39 | I46: ='1994-1995'!T2 -> 41 | ... K46: ='1994-1995'!V2 -> 1
A47: 1994-1995 | B47: ='1994-1995'!M3 -> Manchester United | C47: ='1994-1995'!N3 -> 26 | D47: ='1994-1995'!O3 -> 10 | E47: ='1994-1995'!P3 -> 6 | F47: ='1994-1995'!Q3 -> 42 | G47: ='1994-1995'!R3 -> 77 | H47: ='1994-1995'!S3 -> 28 | I47: ='1994-1995'!T3 -> 49 | ... K47: ='1994-1995'!V3 -> 2
A48: 1994-1995 | B48: ='1994-1995'!M4 -> Nottingham Forest | C48: ='1994-1995'!N4 -> 22 | D48: ='1994-1995'!O4 -> 11 | E48: ='1994-1995'!P4 -> 9 | F48: ='1994-1995'!Q4 -> 42 | G48: ='1994-1995'!R4 -> 72 | H48: ='1994-1995'!S4 -> 43 | I48: ='1994-1995'!T4 -> 29 | ... K48: ='1994-1995'!V4 -> 3
A49: 1994-1995 | B49: ='1994-1995'!M5 -> Liverpool | C49: ='1994-1995'!N5 -> 21 | D49: ='1994-1995'!O5 -> 11 | E49: ='1994-1995'!P5 -> 10 | F49: ='1994-1995'!Q5 -> 42 | G49: ='1994-1995'!R5 -> 65 | H49: ='1994-1995'!S5 -> 37 | I49: ='1994-1995'!T5 -> 28 | ... K49: ='1994-1995'!V5 -> 4
A50: 1994-1995 | B50: ='1994-1995'!M6 -> Leeds | C50: ='1994-1995'!N6 -> 20 | D50: ='1994-1995'!O6 -> 13 | E50: ='1994-1995'!P6 -> 9 | F50: ='1994-1995'!Q6 -> 42 | G50: ='1994-1995'!R6 -> 59 | H50: ='1994-1995'!S6 -> 38 | I50: ='1994-1995'!T6 -> 21 | ... K50: ='1994-1995'!V6 -> 5
A51: 1994-1995 | B51: ='1994-1995'!M7 -> Newcastle | C51: ='1994-1995'!N7 -> 20 | D51: ='1994-1995'!O7 -> 12 | E51: ='1994-1995'!P7 -> 10 | F51: ='1994-1995'!Q7 -> 42 | G51: ='1994-1995'!R7 -> 67 | H51: ='1994-1995'!S7 -> 47 | I51: ='1994-1995'!T7 -> 20 | ... K51: ='1994-1995'!V7 -> 6
A52: 1994-1995 | B52: ='1994-1995'!M8 -> Tottenham | C52: ='1994-1995'!N8 -> 16 | D52: ='1994-1995'!O8 -> 14 | E52: ='1994-1995'!P8 -> 12 | F52: ='1994-1995'!Q8 -> 42 | G52: ='1994-1995'!R8 -> 66 | H52: ='1994-1995'!S8 -> 58 | I52: ='1994-1995'!T8 -> 8 | ... K52: ='1994-1995'!V8 -> 7
A53: 1994-1995 | B53: ='1994-1995'!M9 -> QPR | C53: ='1994-1995'!N9 -> 17 | D53: ='1994-1995'!O9 -> 9 | E53: ='1994-1995'!P9 -> 16 | F53: ='1994-1995'!Q9 -> 42 | G53: ='1994-1995'!R9 -> 61 | H53: ='1994-1995'!S9 -> 59 | I53: ='1994-1995'!T9 -> 2 | ... K53: ='1994-1995'!V9 -> 8
A54: 1994-1995 | B54: ='1994-1995'!M10 -> Wimbledon FC | C54: ='1994-1995'!N10 -> 15 | D54: ='1994-1995'!O10 -> 11 | E54: ='1994-1995'!P10 -> 16 | F54: ='1994-1995'!Q10 -> 42 | G54: ='1994-1995'!R10 -> 48 | H54: ='1994-1995'!S10 -> 65 | I54: ='1994-1995'!T10 -> -17 | ... K54: ='1994-1995'!V10 -> 9
A55: 1994-1995 | B55: ='1994-1995'!M11 -> Southampton | C55: ='1994-1995'!N11 -> 12 | D55: ='1994-1995'!O11 -> 18 | E55: ='1994-1995'!P11 -> 12 | F55: ='1994-1995'!Q11 -> 42 | G55: ='1994-1995'!R11 -> 61 | H55: ='1994-1995'!S11 -> 63 | I55: ='1994-1995'!T11 -> -2 | ... K55: ='1994-1995'!V11 -> 10
A56: 1994-1995 | B56: ='1994-1995'!M12 -> Chelsea | C56: ='1994-1995'!N12 -> 13 | D56: ='1994-1995'!O12 -> 15 | E56: ='1994-1995'!P12 -> 14 | F56: ='1994-1995'!Q12 -> 42 | G56: ='1994-1995'!R12 -> 50 | H56: ='1994-1995'!S12 -> 55 | I56: ='1994-1995'!T12 -> -5 | ... K56: ='1994-1995'!V12 -> 11
A57: 1994-1995 | B57: ='1994-1995'!M13 -> Arsenal | C57: ='1994-1995'!N13 -> 13 | D57: ='1994-1995'!O13 -> 12 | E57: ='1994-1995'!P13 -> 17 | F57: ='1994-1995'!Q13 -> 42 | G57: ='1994-1995'!R13 -> 52 | H57: ='1994-1995'!S13 -> 49 | I57: ='1994-1995'!T13 -> 3 | ... K57: ='1994-1995'!V13 -> 12
... A67: 1994-1995 | B67: ='1994-1995'!M23 -> Ipswich | C67: ='1994-1995'!N23 -> 7 | D67: ='1994-1995'!O23 -> 6 | E67: ='1994-1995'!P23 -> 29 | F67: ='1994-1995'!Q23 -> 42 | G67: ='1994-1995'!R23 -> 36 | H67: ='1994-1995'!S23 -> 93 | I67: ='1994-1995'!T23 -> -57 | ... K67: ='1994-1995'!V23 -> 22
...

Sheet 1992-1993
A1: ID | B1: Date | C1: Round | D1: Home | F1: Away | H1: Winner | I1: Draw-1 | J1: Draw-2 | M1: Team | N1: Wins | O1: Draws | P1: Losses | Q1: Games Played | R1: Goals For | S1: Goals Against | T1: Goal Difference | U1: Points | V1: Position
A2: 947742 | B2: 33831 | C2: Round | D2: Chelsea | E2: 1 | F2: Oldham | G2: 1 | H2: =IF(E2>G2,D2,IF(G2>E2,F2,"")) | I2: =IF(H2="",D2,"") -> Chelsea | J2: =IF(H2="",F2,"") -> Oldham | M2: Manchester United | N2: =COUNTIF($H$2:$H$463,M2) -> 24 | O2: =COUNTIF($J$2:$J$463,M2)+COUNTIF($I$2:$I$463,M2) -> 12 | P2: =(COUNTIF($F$2:$F$463,M2)+COUNTIF($D$2:$D$463,M2))-SUM(N2:O2) -> 6 | Q2: =SUM(N2:P2) -> 42 | R2: =SUMIF(D:D,M2,E:E)+SUMIF(F:F,M2,G:G) -> 67 | S2: =SUMIF(D:D,M2,G:G)+SUMIF(F:F,M2,E:E) -> 31 | T2: =R2-S2 -> 36 | U2: =(N2*3)+O2 -> 84 | V2: 1
A3: 947760 | B3: 33831 | C3: Round | D3: Coventry | E3: 2 | F3: Middlesbrough | G3: 1 | H3: =IF(E3>G3,D3,IF(G3>E3,F3,"")) -> Coventry | I3: =IF(H3="",D3,"") | J3: =IF(H3="",F3,"") | M3: Aston Villa | N3: =COUNTIF($H$2:$H$463,M3) -> 21 | O3: =COUNTIF($J$2:$J$463,M3)+COUNTIF($I$2:$I$463,M3) -> 11 | P3: =(COUNTIF($F$2:$F$463,M3)+COUNTIF($D$2:$D$463,M3))-SUM(N3:O3) -> 10 | Q3: =SUM(N3:P3) -> 42 | R3: =SUMIF(D:D,M3,E:E)+SUMIF(F:F,M3,G:G) -> 57 | S3: =SUMIF(D:D,M3,G:G)+SUMIF(F:F,M3,E:E) -> 40 | T3: =R3-S3 -> 17 | U3: =(N3*3)+O3 -> 74 | V3: 2
A4: 947772 | B4: 33831 | C4: Round | D4: Crystal Palace | E4: 3 | F4: Blackburn | G4: 3 | H4: =IF(E4>G4,D4,IF(G4>E4,F4,"")) | I4: =IF(H4="",D4,"") -> Crystal Palace | J4: =IF(H4="",F4,"") -> Blackburn | M4: Norwich | N4: =COUNTIF($H$2:$H$463,M4) -> 21 | O4: =COUNTIF($J$2:$J$463,M4)+COUNTIF($I$2:$I$463,M4) -> 9 | P4: =(COUNTIF($F$2:$F$463,M4)+COUNTIF($D$2:$D$463,M4))-SUM(N4:O4) -> 12 | Q4: =SUM(N4:P4) -> 42 | R4: =SUMIF(D:D,M4,E:E)+SUMIF(F:F,M4,G:G) -> 61 | S4: =SUMIF(D:D,M4,G:G)+SUMIF(F:F,M4,E:E) -> 65 | T4: =R4-S4 -> -4 | U4: =(N4*3)+O4 -> 72 | V4: 3
A5: 948033 | B5: 33831 | C5: Round | D5: Sheffield United | E5: 2 | F5: Manchester United | G5: 1 | H5: =IF(E5>G5,D5,IF(G5>E5,F5,"")) -> Sheffield United | I5: =IF(H5="",D5,"") | J5: =IF(H5="",F5,"") | M5: Blackburn | N5: =COUNTIF($H$2:$H$463,M5) -> 20 | O5: =COUNTIF($J$2:$J$463,M5)+COUNTIF($I$2:$I$463,M5) -> 11 | P5: =(COUNTIF($F$2:$F$463,M5)+COUNTIF($D$2:$D$463,M5))-SUM(N5:O5) -> 11 | Q5: =SUM(N5:P5) -> 42 | R5: =SUMIF(D:D,M5,E:E)+SUMIF(F:F,M5,G:G) -> 68 | S5: =SUMIF(D:D,M5,G:G)+SUMIF(F:F,M5,E:E) -> 46 | T5: =R5-S5 -> 22 | U5: =(N5*3)+O5 -> 71 | V5: 4
A6: 947808 | B6: 33831 | C6: Round | D6: Everton | E6: 1 | F6: Sheffield Weds | G6: 1 | H6: =IF(E6>G6,D6,IF(G6>E6,F6,"")) | I6: =IF(H6="",D6,"") -> Everton | J6: =IF(H6="",F6,"") -> Sheffield Weds | M6: QPR | N6: =COUNTIF($H$2:$H$463,M6) -> 17 | O6: =COUNTIF($J$2:$J$463,M6)+COUNTIF($I$2:$I$463,M6) -> 12 | P6: =(COUNTIF($F$2:$F$463,M6)+COUNTIF($D$2:$D$463,M6))-SUM(N6:O6) -> 13 | Q6: =SUM(N6:P6) -> 42 | R6: =SUMIF(D:D,M6,E:E)+SUMIF(F:F,M6,G:G) -> 63 | S6: =SUMIF(D:D,M6,G:G)+SUMIF(F:F,M6,E:E) -> 55 | T6: =R6-S6 -> 8 | U6: =(N6*3)+O6 -> 63 | V6: 5
A7: 947813 | B7: 33831 | C7: Round | D7: Ipswich | E7: 1 | F7: Aston Villa | G7: 1 | H7: =IF(E7>G7,D7,IF(G7>E7,F7,"")) | I7: =IF(H7="",D7,"") -> Ipswich | J7: =IF(H7="",F7,"") -> Aston Villa | M7: Liverpool | N7: =COUNTIF($H$2:$H$463,M7) -> 16 | O7: =COUNTIF($J$2:$J$463,M7)+COUNTIF($I$2:$I$463,M7) -> 11 | P7: =(COUNTIF($F$2:$F$463,M7)+COUNTIF($D$2:$D$463,M7))-SUM(N7:O7) -> 15 | Q7: =SUM(N7:P7) -> 42 | R7: =SUMIF(D:D,M7,E:E)+SUMIF(F:F,M7,G:G) -> 62 | S7: =SUMIF(D:D,M7,G:G)+SUMIF(F:F,M7,E:E) -> 55 | T7: =R7-S7 -> 7 | U7: =(N7*3)+O7 -> 59 | V7: 6
A8: 948083 | B8: 33831 | C8: Round | D8: Southampton | E8: 0 | F8: Tottenham | G8: 0 | H8: =IF(E8>G8,D8,IF(G8>E8,F8,"")) | I8: =IF(H8="",D8,"") -> Southampton | J8: =IF(H8="",F8,"") -> Tottenham | M8: Sheffield Weds | N8: =COUNTIF($H$2:$H$463,M8) -> 15 | O8: =COUNTIF($J$2:$J$463,M8)+COUNTIF($I$2:$I$463,M8) -> 14 | P8: =(COUNTIF($F$2:$F$463,M8)+COUNTIF($D$2:$D$463,M8))-SUM(N8:O8) -> 13 | Q8: =SUM(N8:P8) -> 42 | R8: =SUMIF(D:D,M8,E:E)+SUMIF(F:F,M8,G:G) -> 55 | S8: =SUMIF(D:D,M8,G:G)+SUMIF(F:F,M8,E:E) -> 51 | T8: =R8-S8 -> 4 | U8: =(N8*3)+O8 -> 59 | V8: 7
A9: 947853 | B9: 33831 | C9: Round | D9: Leeds | E9: 2 | F9: Wimbledon FC | G9: 1 | H9: =IF(E9>G9,D9,IF(G9>E9,F9,"")) -> Leeds | I9: =IF(H9="",D9,"") | J9: =IF(H9="",F9,"") | M9: Tottenham | N9: =COUNTIF($H$2:$H$463,M9) -> 16 | O9: =COUNTIF($J$2:$J$463,M9)+COUNTIF($I$2:$I$463,M9) -> 11 | P9: =(COUNTIF($F$2:$F$463,M9)+COUNTIF($D$2:$D$463,M9))-SUM(N9:O9) -> 15 | Q9: =SUM(N9:P9) -> 42 | R9: =SUMIF(D:D,M9,E:E)+SUMIF(F:F,M9,G:G) -> 60 | S9: =SUMIF(D:D,M9,G:G)+SUMIF(F:F,M9,E:E) -> 66 | T9: =R9-S9 -> -6 | U9: =(N9*3)+O9 -> 59 | V9: 8
A10: 947677 | B10: 33831 | C10: Round | D10: Arsenal | E10: 2 | F10: Norwich | G10: 4 | H10: =IF(E10>G10,D10,IF(G10>E10,F10,"")) -> Norwich | I10: =IF(H10="",D10,"") | J10: =IF(H10="",F10,"") | M10: Manchester City | N10: =COUNTIF($H$2:$H$463,M10) -> 15 | O10: =COUNTIF($J$2:$J$463,M10)+COUNTIF($I$2:$I$463,M10) -> 12 | P10: =(COUNTIF($F$2:$F$463,M10)+COUNTIF($D$2:$D$463,M10))-SUM(N10:O10) -> 15 | Q10: =SUM(N10:P10) -> 42 | R10: =SUMIF(D:D,M10,E:E)+SUMIF(F:F,M10,G:G) -> 56 | S10: =SUMIF(D:D,M10,G:G)+SUMIF(F:F,M10,E:E) -> 51 | T10: =R10-S10 -> 5 | U10: =(N10*3)+O10 -> 57 | V10: 9
A11: 947968 | B11: 33832 | C11: Round | D11: Nottingham Forest | E11: 1 | F11: Liverpool | G11: 0 | H11: =IF(E11>G11,D11,IF(G11>E11,F11,"")) -> Nottingham Forest | I11: =IF(H11="",D11,"") | J11: =IF(H11="",F11,"") | M11: Arsenal | N11: =COUNTIF($H$2:$H$463,M11) -> 15 | O11: =COUNTIF($J$2:$J$463,M11)+COUNTIF($I$2:$I$463,M11) -> 11 | P11: =(COUNTIF($F$2:$F$463,M11)+COUNTIF($D$2:$D$463,M11))-SUM(N11:O11) -> 16 | Q11: =SUM(N11:P11) -> 42 | R11: =SUMIF(D:D,M11,E:E)+SUMIF(F:F,M11,G:G) -> 40 | S11: =SUMIF(D:D,M11,G:G)+SUMIF(F:F,M11,E:E) -> 38 | T11: =R11-S11 -> 2 | U11: =(N11*3)+O11 -> 56 | V11: 10
A12: 947890 | B12: 33833 | C12: Round | D12: Manchester City | E12: 1 | F12: QPR | G12: 1 | H12: =IF(E12>G12,D12,IF(G12>E12,F12,"")) | I12: =IF(H12="",D12,"") -> Manchester City | J12: =IF(H12="",F12,"") -> QPR | M12: Chelsea | N12: =COUNTIF($H$2:$H$463,M12) -> 14 | O12: =COUNTIF($J$2:$J$463,M12)+COUNTIF($I$2:$I$463,M12) -> 14 | P12: =(COUNTIF($F$2:$F$463,M12)+COUNTIF($D$2:$D$463,M12))-SUM(N12:O12) -> 14 | Q12: =SUM(N12:P12) -> 42 | R12: =SUMIF(D:D,M12,E:E)+SUMIF(F:F,M12,G:G) -> 51 | S12: =SUMIF(D:D,M12,G:G)+SUMIF(F:F,M12,E:E) -> 54 | T12: =R12-S12 -> -3 | U12: =(N12*3)+O12 -> 56 | V12: 11
A13: 948113 | B13: 33834 | C13: Round | D13: Wimbledon FC | E13: 0 | F13: Ipswich | G13: 1 | H13: =IF(E13>G13,D13,IF(G13>E13,F13,"")) -> Ipswich | I13: =IF(H13="",D13,"") | J13: =IF(H13="",F13,"") | M13: Wimbledon FC | N13: =COUNTIF($H$2:$H$463,M13) -> 14 | O13: =COUNTIF($J$2:$J$463,M13)+COUNTIF($I$2:$I$463,M13) -> 12 | P13: =(COUNTIF($F$2:$F$463,M13)+COUNTIF($D$2:$D$463,M13))-SUM(N13:O13) -> 16 | Q13: =SUM(N13:P13) -> 42 | R13: =SUMIF(D:D,M13,E:E)+SUMIF(F:F,M13,G:G) -> 56 | S13: =SUMIF(D:D,M13,G:G)+SUMIF(F:F,M13,E:E) -> 55 | T13: =R13-S13 -> 1 | U13: =(N13*3)+O13 -> 54 | V13: 12
... A23: 947693 | B23: 33835 | C23: Round | D23: Aston Villa | E23: 1 | F23: Leeds | G23: 1 | H23: =IF(E23>G23,D23,IF(G23>E23,F23,"")) | I23: =IF(H23="",D23,"") -> Aston Villa | J23: =IF(H23="",F23,"") -> Leeds | M23: Nottingham Forest | N23: =COUNTIF($H$2:$H$463,M23) -> 10 | O23: =COUNTIF($J$2:$J$463,M23)+COUNTIF($I$2:$I$463,M23) -> 10 | P23: =(COUNTIF($F$2:$F$463,M23)+COUNTIF($D$2:$D$463,M23))-SUM(N23:O23) -> 22 | Q23: =SUM(N23:P23) -> 42 | R23: =SUMIF(D:D,M23,E:E)+SUMIF(F:F,M23,G:G) -> 41 | S23: =SUMIF(D:D,M23,G:G)+SUMIF(F:F,M23,E:E) -> 62 | T23: =R23-S23 -> -21 | U23: =(N23*3)+O23 -> 40 | V23: 22
A24: 947716 | B24: 33838 | C24: Round | D24: Blackburn | E24: 1 | F24: Manchester City | G24: 0 | H24: =IF(E24>G24,D24,IF(G24>E24,F24,"")) -> Blackburn | I24: =IF(H24="",D24,"") | J24: =IF(H24="",F24,"")
A25: 947994 | B25: 33838 | C25: Round | D25: Oldham | E25: 5 | F25: Nottingham Forest | G25: 3 | H25: =IF(E25>G25,D25,IF(G25>E25,F25,"")) -> Oldham | I25: =IF(H25="",D25,"") | J25: =IF(H25="",F25,"")
A26: 948017 | B26: 33838 | C26: Round | D26: QPR | E26: 3 | F26: Sheffield United | G26: 2 | H26: =IF(E26>G26,D26,IF(G26>E26,F26,"")) -> QPR | I26: =IF(H26="",D26,"") | J26: =IF(H26="",F26,"")
A27: 948046 | B27: 33838 | C27: Round | D27: Sheffield Weds | E27: 3 | F27: Chelsea | G27: 3 | H27: =IF(E27>G27,D27,IF(G27>E27,F27,"")) | I27: =IF(H27="",D27,"") -> Sheffield Weds | J27: =IF(H27="",F27,"") -> Chelsea
A28: 948090 | B28: 33838 | C28: Round | D28: Tottenham | E28: 2 | F28: Crystal Palace | G28: 2 | H28: =IF(E28>G28,D28,IF(G28>E28,F28,"")) | I28: =IF(H28="",D28,"") -> Tottenham | J28: =IF(H28="",F28,"") -> Crystal Palace
A29: 948110 | B29: 33838 | C29: Round | D29: Wimbledon FC | E29: 1 | F29: Coventry | G29: 2 | H29: =IF(E29>G29,D29,IF(G29>E29,F29,"")) -> Coventry | I29: =IF(H29="",D29,"") | J29: =IF(H29="",F29,"")
A30: 947903 | B30: 33838 | C30: Round | D30: Manchester United | E30: 1 | F30: Ipswich | G30: 1 | H30: =IF(E30>G30,D30,IF(G30>E30,F30,"")) | I30: =IF(H30="",D30,"") -> Manchester United | J30: =IF(H30="",F30,"") -> Ipswich
A31: 947925 | B31: 33838 | C31: Round | D31: Middlesbrough | E31: 4 | F31: Leeds | G31: 1 | H31: =IF(E31>G31,D31,IF(G31>E31,F31,"")) -> Middlesbrough | I31: =IF(H31="",D31,"") | J31: =IF(H31="",F31,"")
A32: 947944 | B32: 33838 | C32: Round | D32: Norwich | E32: 1 | F32: Everton | G32: 1 | H32: =IF(E32>G32,D32,IF(G32>E32,F32,"")) | I32: =IF(H32="",D32,"") -> Norwich | J32: =IF(H32="",F32,"") -> Everton
A33: 947704 | B33: 33838 | C33: Round | D33: Aston Villa | E33: 1 | F33: Southampton | G33: 1 | H33: =IF(E33>G33,D33,IF(G33>E33,F33,"")) | I33: =IF(H33="",D33,"") -> Aston Villa | J33: =IF(H33="",F33,"") -> Southampton
A34: 947854 | B34: 33839 | C34: Round | D34: Liverpool | E34: 0 | F34: Arsenal | G34: 2 | H34: =IF(E34>G34,D34,IF(G34>E34,F34,"")) -> Arsenal | I34: =IF(H34="",D34,"") | J34: =IF(H34="",F34,"")
A35: 948075 | B35: 33840 | C35: Round | D35: Southampton | E35: 0 | F35: Manchester United | G35: 1 | H35: =IF(E35>G35,D35,IF(G35>E35,F35,"")) -> Manchester United | I35: =IF(H35="",D35,"") | J35: =IF(H35="",F35,"")
... A463: 947684 | B463: 34100 | C463: Round | D463: Arsenal | E463: 1 | F463: Tottenham | G463: 3 | H463: =IF(E463>G463,D463,IF(G463>E463,F463,"")) -> Tottenham | I463: =IF(H463="",D463,"") | J463: =IF(H463="",F463,"")

Sheet 1993-1994
A1: ID | B1: Date | C1: Round | D1: Home | F1: Away | H1: Winner | I1: Draw-1 | J1: Draw-2 | M1: Team | N1: Wins | O1: Draws | P1: Losses | Q1: Games Played | R1: Goals For | S1: Goals Against | T1: Goal Difference | U1: Points | V1: Position
A2: 948489 | B2: 34195 | C2: Round | D2: Southampton | E2: 0 | F2: Everton | G2: 2 | H2: =IF(E2>G2,D2,IF(G2>E2,F2,"")) -> Everton | I2: =IF(H2="",D2,"") | J2: =IF(H2="",F2,"") | M2: Manchester United | N2: =COUNTIF($H$2:$H$463,M2) -> 27 | O2: =COUNTIF($J$2:$J$463,M2)+COUNTIF($I$2:$I$463,M2) -> 11 | P2: =(COUNTIF($F$2:$F$463,M2)+COUNTIF($D$2:$D$463,M2))-SUM(N2:O2) -> 4 | Q2: =SUM(N2:P2) -> 42 | R2: =SUMIF(D:D,M2,E:E)+SUMIF(F:F,M2,G:G) -> 80 | S2: =SUMIF(D:D,M2,G:G)+SUMIF(F:F,M2,E:E) -> 38 | T2: =R2-S2 -> 42 | U2: =(N2*3)+O2 -> 92 | V2: 1
A3: 948310 | B3: 34195 | C3: Round | D3: Liverpool | E3: 2 | F3: Sheffield Weds | G3: 0 | H3: =IF(E3>G3,D3,IF(G3>E3,F3,"")) -> Liverpool | I3: =IF(H3="",D3,"") | J3: =IF(H3="",F3,"") | M3: Blackburn | N3: =COUNTIF($H$2:$H$463,M3) -> 25 | O3: =COUNTIF($J$2:$J$463,M3)+COUNTIF($I$2:$I$463,M3) -> 9 | P3: =(COUNTIF($F$2:$F$463,M3)+COUNTIF($D$2:$D$463,M3))-SUM(N3:O3) -> 8 | Q3: =SUM(N3:P3) -> 42 | R3: =SUMIF(D:D,M3,E:E)+SUMIF(F:F,M3,G:G) -> 63 | S3: =SUMIF(D:D,M3,G:G)+SUMIF(F:F,M3,E:E) -> 36 | T3: =R3-S3 -> 27 | U3: =(N3*3)+O3 -> 84 | V3: 2
A4: 948567 | B4: 34195 | C4: Round | D4: West Ham | E4: 0 | F4: Wimbledon FC | G4: 2 | H4: =IF(E4>G4,D4,IF(G4>E4,F4,"")) -> Wimbledon FC | I4: =IF(H4="",D4,"") | J4: =IF(H4="",F4,"") | M4: Newcastle | N4: =COUNTIF($H$2:$H$463,M4) -> 23 | O4: =COUNTIF($J$2:$J$463,M4)+COUNTIF($I$2:$I$463,M4) -> 8 | P4: =(COUNTIF($F$2:$F$463,M4)+COUNTIF($D$2:$D$463,M4))-SUM(N4:O4) -> 11 | Q4: =SUM(N4:P4) -> 42 | R4: =SUMIF(D:D,M4,E:E)+SUMIF(F:F,M4,G:G) -> 82 | S4: =SUMIF(D:D,M4,G:G)+SUMIF(F:F,M4,E:E) -> 41 | T4: =R4-S4 -> 41 | U4: =(N4*3)+O4 -> 77 | V4: 3
A5: 948323 | B5: 34195 | C5: Round | D5: Manchester City | E5: 1 | F5: Leeds | G5: 1 | H5: =IF(E5>G5,D5,IF(G5>E5,F5,"")) | I5: =IF(H5="",D5,"") -> Manchester City | J5: =IF(H5="",F5,"") -> Leeds | M5: Arsenal | N5: =COUNTIF($H$2:$H$463,M5) -> 18 | O5: =COUNTIF($J$2:$J$463,M5)+COUNTIF($I$2:$I$463,M5) -> 17 | P5: =(COUNTIF($F$2:$F$463,M5)+COUNTIF($D$2:$D$463,M5))-SUM(N5:O5) -> 7 | Q5: =SUM(N5:P5) -> 42 | R5: =SUMIF(D:D,M5,E:E)+SUMIF(F:F,M5,G:G) -> 53 | S5: =SUMIF(D:D,M5,G:G)+SUMIF(F:F,M5,E:E) -> 28 | T5: =R5-S5 -> 25 | U5: =(N5*3)+O5 -> 71 | V5: 4
A6: 948376 | B6: 34195 | C6: Round | D6: Newcastle | E6: 0 | F6: Tottenham | G6: 1 | H6: =IF(E6>G6,D6,IF(G6>E6,F6,"")) -> Tottenham | I6: =IF(H6="",D6,"") | J6: =IF(H6="",F6,"") | M6: Leeds | N6: =COUNTIF($H$2:$H$463,M6) -> 18 | O6: =COUNTIF($J$2:$J$463,M6)+COUNTIF($I$2:$I$463,M6) -> 16 | P6: =(COUNTIF($F$2:$F$463,M6)+COUNTIF($D$2:$D$463,M6))-SUM(N6:O6) -> 8 | Q6: =SUM(N6:P6) -> 42 | R6: =SUMIF(D:D,M6,E:E)+SUMIF(F:F,M6,G:G) -> 65 | S6: =SUMIF(D:D,M6,G:G)+SUMIF(F:F,M6,E:E) -> 39 | T6: =R6-S6 -> 26 | U6: =(N6*3)+O6 -> 70 | V6: 5
A7: 948130 | B7: 34195 | C7: Round | D7: Arsenal | E7: 0 | F7: Coventry | G7: 3 | H7: =IF(E7>G7,D7,IF(G7>E7,F7,"")) -> Coventry | I7: =IF(H7="",D7,"") | J7: =IF(H7="",F7,"") | M7: Wimbledon FC | N7: =COUNTIF($H$2:$H$463,M7) -> 18 | O7: =COUNTIF($J$2:$J$463,M7)+COUNTIF($I$2:$I$463,M7) -> 11 | P7: =(COUNTIF($F$2:$F$463,M7)+COUNTIF($D$2:$D$463,M7))-SUM(N7:O7) -> 13 | Q7: =SUM(N7:P7) -> 42 | R7: =SUMIF(D:D,M7,E:E)+SUMIF(F:F,M7,G:G) -> 56 | S7: =SUMIF(D:D,M7,G:G)+SUMIF(F:F,M7,E:E) -> 53 | T7: =R7-S7 -> 3 | U7: =(N7*3)+O7 -> 65 | V7: 6
A8: 948406 | B8: 34195 | C8: Round | D8: Oldham | E8: 0 | F8: Ipswich | G8: 3 | H8: =IF(E8>G8,D8,IF(G8>E8,F8,"")) -> Ipswich | I8: =IF(H8="",D8,"") | J8: =IF(H8="",F8,"") | M8: Sheffield Weds | N8: =COUNTIF($H$2:$H$463,M8) -> 16 | O8: =COUNTIF($J$2:$J$463,M8)+COUNTIF($I$2:$I$463,M8) -> 16 | P8: =(COUNTIF($F$2:$F$463,M8)+COUNTIF($D$2:$D$463,M8))-SUM(N8:O8) -> 10 | Q8: =SUM(N8:P8) -> 42 | R8: =SUMIF(D:D,M8,E:E)+SUMIF(F:F,M8,G:G) -> 76 | S8: =SUMIF(D:D,M8,G:G)+SUMIF(F:F,M8,E:E) -> 54 | T8: =R8-S8 -> 22 | U8: =(N8*3)+O8 -> 64 | V8: 7
A9: 948161 | B9: 34195 | C9: Round | D9: Aston Villa | E9: 4 | F9: QPR | G9: 1 | H9: =IF(E9>G9,D9,IF(G9>E9,F9,"")) -> Aston Villa | I9: =IF(H9="",D9,"") | J9: =IF(H9="",F9,"") | M9: Liverpool | N9: =COUNTIF($H$2:$H$463,M9) -> 17 | O9: =COUNTIF($J$2:$J$463,M9)+COUNTIF($I$2:$I$463,M9) -> 9 | P9: =(COUNTIF($F$2:$F$463,M9)+COUNTIF($D$2:$D$463,M9))-SUM(N9:O9) -> 16 | Q9: =SUM(N9:P9) -> 42 | R9: =SUMIF(D:D,M9,E:E)+SUMIF(F:F,M9,G:G) -> 59 | S9: =SUMIF(D:D,M9,G:G)+SUMIF(F:F,M9,E:E) -> 55 | T9: =R9-S9 -> 4 | U9: =(N9*3)+O9 -> 60 | V9: 8
A10: 948192 | B10: 34195 | C10: Round | D10: Chelsea | E10: 1 | F10: Blackburn | G10: 2 | H10: =IF(E10>G10,D10,IF(G10>E10,F10,"")) -> Blackburn | I10: =IF(H10="",D10,"") | J10: =IF(H10="",F10,"") | M10: QPR | N10: =COUNTIF($H$2:$H$463,M10) -> 16 | O10: =COUNTIF($J$2:$J$463,M10)+COUNTIF($I$2:$I$463,M10) -> 12 | P10: =(COUNTIF($F$2:$F$463,M10)+COUNTIF($D$2:$D$463,M10))-SUM(N10:O10) -> 14 | Q10: =SUM(N10:P10) -> 42 | R10: =SUMIF(D:D,M10,E:E)+SUMIF(F:F,M10,G:G) -> 62 | S10: =SUMIF(D:D,M10,G:G)+SUMIF(F:F,M10,E:E) -> 61 | T10: =R10-S10 -> 1 | U10: =(N10*3)+O10 -> 60 | V10: 9
A11: 948459 | B11: 34195 | C11: Round | D11: Sheffield United | E11: 3 | F11: Swindon | G11: 1 | H11: =IF(E11>G11,D11,IF(G11>E11,F11,"")) -> Sheffield United | I11: =IF(H11="",D11,"") | J11: =IF(H11="",F11,"") | M11: Aston Villa | N11: =COUNTIF($H$2:$H$463,M11) -> 15 | O11: =COUNTIF($J$2:$J$463,M11)+COUNTIF($I$2:$I$463,M11) -> 12 | P11: =(COUNTIF($F$2:$F$463,M11)+COUNTIF($D$2:$D$463,M11))-SUM(N11:O11) -> 15 | Q11: =SUM(N11:P11) -> 42 | R11: =SUMIF(D:D,M11,E:E)+SUMIF(F:F,M11,G:G) -> 46 | S11: =SUMIF(D:D,M11,G:G)+SUMIF(F:F,M11,E:E) -> 50 | T11: =R11-S11 -> -4 | U11: =(N11*3)+O11 -> 57 | V11: 10
A12: 948389 | B12: 34196 | C12: Round | D12: Norwich | E12: 0 | F12: Manchester United | G12: 2 | H12: =IF(E12>G12,D12,IF(G12>E12,F12,"")) -> Manchester United | I12: =IF(H12="",D12,"") | J12: =IF(H12="",F12,"") | M12: Coventry | N12: =COUNTIF($H$2:$H$463,M12) -> 14 | O12: =COUNTIF($J$2:$J$463,M12)+COUNTIF($I$2:$I$463,M12) -> 14 | P12: =(COUNTIF($F$2:$F$463,M12)+COUNTIF($D$2:$D$463,M12))-SUM(N12:O12) -> 14 | Q12: =SUM(N12:P12) -> 42 | R12: =SUMIF(D:D,M12,E:E)+SUMIF(F:F,M12,G:G) -> 43 | S12: =SUMIF(D:D,M12,G:G)+SUMIF(F:F,M12,E:E) -> 45 | T12: =R12-S12 -> -2 | U12: =(N12*3)+O12 -> 56 | V12: 11
A13: 948526 | B13: 34197 | C13: Round | D13: Tottenham | E13: 0 | F13: Arsenal | G13: 1 | H13: =IF(E13>G13,D13,IF(G13>E13,F13,"")) -> Arsenal | I13: =IF(H13="",D13,"") | J13: =IF(H13="",F13,"") | M13: Norwich | N13: =COUNTIF($H$2:$H$463,M13) -> 12 | O13: =COUNTIF($J$2:$J$463,M13)+COUNTIF($I$2:$I$463,M13) -> 17 | P13: =(COUNTIF($F$2:$F$463,M13)+COUNTIF($D$2:$D$463,M13))-SUM(N13:O13) -> 13 | Q13: =SUM(N13:P13) -> 42 | R13: =SUMIF(D:D,M13,E:E)+SUMIF(F:F,M13,G:G) -> 65 | S13: =SUMIF(D:D,M13,G:G)+SUMIF(F:F,M13,E:E) -> 61 | T13: =R13-S13 -> 4 | U13: =(N13*3)+O13 -> 53 | V13: 12
... A23: 948221 | B23: 34199 | C23: Round | D23: Coventry | E23: 2 | F23: Newcastle | G23: 1 | H23: =IF(E23>G23,D23,IF(G23>E23,F23,"")) -> Coventry | I23: =IF(H23="",D23,"") | J23: =IF(H23="",F23,"") | M23: Swindon | N23: =COUNTIF($H$2:$H$463,M23) -> 5 | O23: =COUNTIF($J$2:$J$463,M23)+COUNTIF($I$2:$I$463,M23) -> 15 | P23: =(COUNTIF($F$2:$F$463,M23)+COUNTIF($D$2:$D$463,M23))-SUM(N23:O23) -> 22 | Q23: =SUM(N23:P23) -> 42 | R23: =SUMIF(D:D,M23,E:E)+SUMIF(F:F,M23,G:G) -> 47 | S23: =SUMIF(D:D,M23,G:G)+SUMIF(F:F,M23,E:E) -> 100 | T23: =R23-S23 -> -53 | U23: =(N23*3)+O23 -> 30 | V23: 22
A24: 948230 | B24: 34202 | C24: Round | D24: Coventry | E24: 1 | F24: West Ham | G24: 1 | H24: =IF(E24>G24,D24,IF(G24>E24,F24,"")) | I24: =IF(H24="",D24,"") -> Coventry | J24: =IF(H24="",F24,"") -> West Ham
A25: 948246 | B25: 34202 | C25: Round | D25: Everton | E25: 4 | F25: Sheffield United | G25: 2 | H25: =IF(E25>G25,D25,IF(G25>E25,F25,"")) -> Everton | I25: =IF(H25="",D25,"") | J25: =IF(H25="",F25,"")
